{"http_interactions": [{"request": {"body": {"encoding": "utf-8", "string": ""}, "headers": {"User-Agent": ["python-requests/2.28.0"], "Accept-Encoding": ["gzip, deflate"], "Accept": ["*/*"], "Connection": ["keep-alive"], "X-Requested-With": ["XMLHttpRequest"], "PyKechain-Version": ["4.2.0"], "Authorization": ["Token <AUTH_TOKEN>"]}, "method": "GET", "uri": "<API_URL>/api/v3/scopes.json?status=ACTIVE&name=Bike+Project&fields=id%2Cname%2Cref%2Ctext%2Ccreated_at%2Cupdated_at%2Cstart_date%2Cdue_date%2Cstatus%2Ccategory%2Cprogress%2Cmembers%2Cteam%2Ctags%2Cscope_options%2Cteam_id_name%2Cworkflow_root_id%2Ccatalog_root_id%2Capp_root_id%2Cproduct_model_id%2Cproduct_instance_id%2Ccatalog_model_id%2Ccatalog_instance_id%2Cproject_info&limit=2"}, "response": {"body": {"encoding": "utf-8", "base64_string": "H4sIAAAAAAAAA7VVTY/jNgz9K4GvjQJ9WbZz2naxhz20HXRme2gxCGibzqhjW4YsZzcY5L+XcjYTB4O2l+khQPjERz6SEv2SVG7qQ7IV66THb/Snn9p2nQweD9ZN48X2OE5tIPPPl8TWyTYp67SuEICBSpHprOSsaKqU5VmqBW80pKZJKCZ0SN4/2Wdc3Xn3F1YhidGaGIJANryCYU6ffPdaTSPWq+BWAcewujs+Y/UEtl9BX6+GaXxa2TCfPuGqtZ0laetkDBCi5OTHjw+ff/9ESAUB984fCfty/+m33f3HX+9m3COd1DuIGSUXBROcSfnA8y03W51v8kynKv2DXKehXrpKybhhkj8IuU3TrRIbJVOjRXQNsI8dmgsj8xsbKzcgC+D3GJJHEhjtnRuCdT15viTugN7bGu/pV4JPtg20I8YG0QBG7Kmgsyu13YfjEHtZTWNw3efK9bEQ1zd2H0PVdhxaOM547G11rNqoYoH/7OoYwON+ainZ6USSztF+gYPdz7ko1eMpDgO6na135/md70CHXYn+egdkbqg9I/rvQx6nAf3Bjs5fB0//7LiDKtgDmcFPVBx2YNvXs3PUy1kEoIc9XntB0CLy1a9FqC/k2fW0Pusq1I2seIGi7/8p6oouVUX2RdRbTZeQ7yLrFflvVTe90m9kRfOq6QtZqweC/00cfCg3ffuenbvRKN7esluR9wvoH0U+udjyMaD/YbCdYrHWD7SA5rWyqVz37pN/jGt0XmY72zcuvqx5R/mwiyvl8qzqCW9s4uzp8dM745si50pnptBGKc2LdfLV+eemdV933jkKGzcxF7w2hmum06pkOq80y3WaMaOalOfSgM6b8yqE1u0XxLpBTSubM10YyXRTACt0LliGpawhF5mWQEQYhgVJlaByjZrJLBNE4pwBZWGlzBthUlVzaZK5iHqiwjtaOe2ZWeS5LoTUTBS6YNpwxQoEyYQuCl0CrVYOC6btqVV9hWcyGJ4p1CVLCwFUqVCUMYvfHDACSgmqUosiF2lLY4SuUsFkmhJTYsFyJXOmhTQZClVDli2Yt2kLToGxEAxzYYjCgZUVCRDG0FdDp9BIlZweT38Dgm4Y4EcHAAA=", "string": ""}, "headers": {"Server": ["nginx"], "Date": ["Mon, 20 Jun 2022 12:55:39 GMT"], "Content-Type": ["application/json"], "Transfer-Encoding": ["chunked"], "Connection": ["keep-alive"], "Vary": ["Accept-Encoding", "Accept, Accept-Language, Cookie"], "allow": ["GET, POST, HEAD, OPTIONS"], "x-frame-options": ["SAMEORIGIN"], "content-language": ["en", "En"], "strict-transport-security": ["max-age=15768000; includeSubDomains"], "x-content-type-options": ["nosniff"], "x-xss-protection": ["1; mode=block"], "referrer-policy": ["same-origin"], "Ke-Chain": ["3"], "Content-Encoding": ["gzip"]}, "status": {"code": 200, "message": "OK"}, "url": "<API_URL>/api/v3/scopes.json?status=ACTIVE&name=Bike+Project&fields=id%2Cname%2Cref%2Ctext%2Ccreated_at%2Cupdated_at%2Cstart_date%2Cdue_date%2Cstatus%2Ccategory%2Cprogress%2Cmembers%2Cteam%2Ctags%2Cscope_options%2Cteam_id_name%2Cworkflow_root_id%2Ccatalog_root_id%2Capp_root_id%2Cproduct_model_id%2Cproduct_instance_id%2Ccatalog_model_id%2Ccatalog_instance_id%2Cproject_info&limit=2"}, "recorded_at": "2022-06-20T12:55:39"}, {"request": {"body": {"encoding": "utf-8", "string": "{\"username\": \"__delete_me\", \"email\": \"hostmaster+newuser@ke-works.com\", \"name\": \"__Nieuwe Gebruiker made for a pykechain test - safe to delete\", \"timezone\": \"Europe/Amsterdam\", \"language_code\": \"nl\", \"team_ids\": []}"}, "headers": {"User-Agent": ["python-requests/2.28.0"], "Accept-Encoding": ["gzip, deflate"], "Accept": ["*/*"], "Connection": ["keep-alive"], "X-Requested-With": ["XMLHttpRequest"], "PyKechain-Version": ["4.2.0"], "Authorization": ["Token <AUTH_TOKEN>"], "Content-Length": ["215"], "Content-Type": ["application/json"]}, "method": "POST", "uri": "<API_URL>/api/users.json"}, "response": {"body": {"encoding": "utf-8", "string": "{\"msg\": \"duplicate key value violates unique constraint \\\"users_user_username_key\\\"\\nDETAIL:  Key (username)=(__delete_me) already exists.\\n\", \"detail\": null, \"traceback\": \"Traceback (most recent call last):\\n  File \\\"/opt/ke-chain/pim3-test/_venv/lib/python3.8/site-packages/django/db/backends/utils.py\\\", line 84, in _execute\\n    return self.cursor.execute(sql, params)\\npsycopg2.errors.UniqueViolation: duplicate key value violates unique constraint \\\"users_user_username_key\\\"\\nDETAIL:  Key (username)=(__delete_me) already exists.\\n\\n\\nThe above exception was the direct cause of the following exception:\\n\\nTraceback (most recent call last):\\n  File \\\"/opt/ke-chain/pim3-test/_venv/lib/python3.8/site-packages/asgiref/sync.py\\\", line 482, in thread_handler\\n    raise exc_info[1]\\n  File \\\"/opt/ke-chain/pim3-test/_venv/lib/python3.8/site-packages/django/core/handlers/base.py\\\", line 233, in _get_response_async\\n    response = await wrapped_callback(request, *callback_args, **callback_kwargs)\\n  File \\\"/opt/ke-chain/pim3-test/_venv/lib/python3.8/site-packages/asgiref/sync.py\\\", line 444, in __call__\\n    ret = await asyncio.wait_for(future, timeout=None)\\n  File \\\"/opt/rh/rh-python38/root/usr/lib64/python3.8/asyncio/tasks.py\\\", line 455, in wait_for\\n    return await fut\\n  File \\\"/opt/ke-chain/pim3-test/_venv/lib/python3.8/site-packages/asgiref/current_thread_executor.py\\\", line 22, in run\\n    result = self.fn(*self.args, **self.kwargs)\\n  File \\\"/opt/ke-chain/pim3-test/_venv/lib/python3.8/site-packages/asgiref/sync.py\\\", line 486, in thread_handler\\n    return func(*args, **kwargs)\\n  File \\\"/opt/ke-chain/pim3-test/_venv/lib/python3.8/site-packages/sentry_sdk/integrations/django/views.py\\\", line 67, in sentry_wrapped_callback\\n    return callback(request, *args, **kwargs)\\n  File \\\"/opt/ke-chain/pim3-test/_venv/lib/python3.8/site-packages/django/views/decorators/csrf.py\\\", line 54, in wrapped_view\\n    return view_func(*args, **kwargs)\\n  File \\\"/opt/ke-chain/pim3-test/_venv/lib/python3.8/site-packages/rest_framework/viewsets.py\\\", line 125, in view\\n    return self.dispatch(request, *args, **kwargs)\\n  File \\\"/opt/ke-chain/pim3-test/_venv/lib/python3.8/site-packages/rest_framework/views.py\\\", line 509, in dispatch\\n    response = self.handle_exception(exc)\\n  File \\\"/opt/ke-chain/pim3-test/_venv/lib/python3.8/site-packages/rest_framework/views.py\\\", line 469, in handle_exception\\n    self.raise_uncaught_exception(exc)\\n  File \\\"/opt/ke-chain/pim3-test/_venv/lib/python3.8/site-packages/rest_framework/views.py\\\", line 480, in raise_uncaught_exception\\n    raise exc\\n  File \\\"/opt/ke-chain/pim3-test/_venv/lib/python3.8/site-packages/rest_framework/views.py\\\", line 506, in dispatch\\n    response = handler(request, *args, **kwargs)\\n  File \\\"/opt/ke-chain/pim3-test/_venv/lib/python3.8/site-packages/rest_framework/mixins.py\\\", line 19, in create\\n    self.perform_create(serializer)\\n  File \\\"/opt/ke-chain/pim3-test/_venv/lib/python3.8/site-packages/rest_framework/mixins.py\\\", line 24, in perform_create\\n    serializer.save()\\n  File \\\"/opt/ke-chain/pim3-test/_venv/lib/python3.8/site-packages/rest_framework/serializers.py\\\", line 212, in save\\n    self.instance = self.create(validated_data)\\n  File \\\"/opt/ke-chain/pim3-test/kechain2/users/api/serializers.py\\\", line 199, in create\\n    return self.Meta.model.create_action(**validated_data)\\n  File \\\"/opt/ke-chain/pim3-test/kechain2/users/models.py\\\", line 99, in create_action\\n    user.save()\\n  File \\\"/opt/ke-chain/pim3-test/_venv/lib/python3.8/site-packages/django/contrib/auth/base_user.py\\\", line 67, in save\\n    super().save(*args, **kwargs)\\n  File \\\"/opt/ke-chain/pim3-test/_venv/lib/python3.8/site-packages/django/db/models/base.py\\\", line 739, in save\\n    self.save_base(using=using, force_insert=force_insert,\\n  File \\\"/opt/ke-chain/pim3-test/_venv/lib/python3.8/site-packages/django/db/models/base.py\\\", line 776, in save_base\\n    updated = self._save_table(\\n  File \\\"/opt/ke-chain/pim3-test/_venv/lib/python3.8/site-packages/django/db/models/base.py\\\", line 881, in _save_table\\n    results = self._do_insert(cls._base_manager, using, fields, returning_fields, raw)\\n  File \\\"/opt/ke-chain/pim3-test/_venv/lib/python3.8/site-packages/django/db/models/base.py\\\", line 919, in _do_insert\\n    return manager._insert(\\n  File \\\"/opt/ke-chain/pim3-test/_venv/lib/python3.8/site-packages/django/db/models/manager.py\\\", line 85, in manager_method\\n    return getattr(self.get_queryset(), name)(*args, **kwargs)\\n  File \\\"/opt/ke-chain/pim3-test/_venv/lib/python3.8/site-packages/django/db/models/query.py\\\", line 1270, in _insert\\n    return query.get_compiler(using=using).execute_sql(returning_fields)\\n  File \\\"/opt/ke-chain/pim3-test/_venv/lib/python3.8/site-packages/django/db/models/sql/compiler.py\\\", line 1416, in execute_sql\\n    cursor.execute(sql, params)\\n  File \\\"/opt/ke-chain/pim3-test/_venv/lib/python3.8/site-packages/django/db/backends/utils.py\\\", line 98, in execute\\n    return super().execute(sql, params)\\n  File \\\"/opt/ke-chain/pim3-test/_venv/lib/python3.8/site-packages/sentry_sdk/integrations/django/__init__.py\\\", line 544, in execute\\n    return real_execute(self, sql, params)\\n  File \\\"/opt/ke-chain/pim3-test/_venv/lib/python3.8/site-packages/django/db/backends/utils.py\\\", line 66, in execute\\n    return self._execute_with_wrappers(sql, params, many=False, executor=self._execute)\\n  File \\\"/opt/ke-chain/pim3-test/_venv/lib/python3.8/site-packages/django/db/backends/utils.py\\\", line 75, in _execute_with_wrappers\\n    return executor(sql, params, many, context)\\n  File \\\"/opt/ke-chain/pim3-test/_venv/lib/python3.8/site-packages/django/db/backends/utils.py\\\", line 84, in _execute\\n    return self.cursor.execute(sql, params)\\n  File \\\"/opt/ke-chain/pim3-test/_venv/lib/python3.8/site-packages/django/db/utils.py\\\", line 90, in __exit__\\n    raise dj_exc_value.with_traceback(traceback) from exc_value\\n  File \\\"/opt/ke-chain/pim3-test/_venv/lib/python3.8/site-packages/django/db/backends/utils.py\\\", line 84, in _execute\\n    return self.cursor.execute(sql, params)\\ndjango.db.utils.IntegrityError: duplicate key value violates unique constraint \\\"users_user_username_key\\\"\\nDETAIL:  Key (username)=(__delete_me) already exists.\\n\\n\", \"results\": [{\"msg\": \"duplicate key value violates unique constraint \\\"users_user_username_key\\\"\\nDETAIL:  Key (username)=(__delete_me) already exists.\\n\", \"detail\": null, \"traceback\": \"Traceback (most recent call last):\\n  File \\\"/opt/ke-chain/pim3-test/_venv/lib/python3.8/site-packages/django/db/backends/utils.py\\\", line 84, in _execute\\n    return self.cursor.execute(sql, params)\\npsycopg2.errors.UniqueViolation: duplicate key value violates unique constraint \\\"users_user_username_key\\\"\\nDETAIL:  Key (username)=(__delete_me) already exists.\\n\\n\\nThe above exception was the direct cause of the following exception:\\n\\nTraceback (most recent call last):\\n  File \\\"/opt/ke-chain/pim3-test/_venv/lib/python3.8/site-packages/asgiref/sync.py\\\", line 482, in thread_handler\\n    raise exc_info[1]\\n  File \\\"/opt/ke-chain/pim3-test/_venv/lib/python3.8/site-packages/django/core/handlers/base.py\\\", line 233, in _get_response_async\\n    response = await wrapped_callback(request, *callback_args, **callback_kwargs)\\n  File \\\"/opt/ke-chain/pim3-test/_venv/lib/python3.8/site-packages/asgiref/sync.py\\\", line 444, in __call__\\n    ret = await asyncio.wait_for(future, timeout=None)\\n  File \\\"/opt/rh/rh-python38/root/usr/lib64/python3.8/asyncio/tasks.py\\\", line 455, in wait_for\\n    return await fut\\n  File \\\"/opt/ke-chain/pim3-test/_venv/lib/python3.8/site-packages/asgiref/current_thread_executor.py\\\", line 22, in run\\n    result = self.fn(*self.args, **self.kwargs)\\n  File \\\"/opt/ke-chain/pim3-test/_venv/lib/python3.8/site-packages/asgiref/sync.py\\\", line 486, in thread_handler\\n    return func(*args, **kwargs)\\n  File \\\"/opt/ke-chain/pim3-test/_venv/lib/python3.8/site-packages/sentry_sdk/integrations/django/views.py\\\", line 67, in sentry_wrapped_callback\\n    return callback(request, *args, **kwargs)\\n  File \\\"/opt/ke-chain/pim3-test/_venv/lib/python3.8/site-packages/django/views/decorators/csrf.py\\\", line 54, in wrapped_view\\n    return view_func(*args, **kwargs)\\n  File \\\"/opt/ke-chain/pim3-test/_venv/lib/python3.8/site-packages/rest_framework/viewsets.py\\\", line 125, in view\\n    return self.dispatch(request, *args, **kwargs)\\n  File \\\"/opt/ke-chain/pim3-test/_venv/lib/python3.8/site-packages/rest_framework/views.py\\\", line 509, in dispatch\\n    response = self.handle_exception(exc)\\n  File \\\"/opt/ke-chain/pim3-test/_venv/lib/python3.8/site-packages/rest_framework/views.py\\\", line 469, in handle_exception\\n    self.raise_uncaught_exception(exc)\\n  File \\\"/opt/ke-chain/pim3-test/_venv/lib/python3.8/site-packages/rest_framework/views.py\\\", line 480, in raise_uncaught_exception\\n    raise exc\\n  File \\\"/opt/ke-chain/pim3-test/_venv/lib/python3.8/site-packages/rest_framework/views.py\\\", line 506, in dispatch\\n    response = handler(request, *args, **kwargs)\\n  File \\\"/opt/ke-chain/pim3-test/_venv/lib/python3.8/site-packages/rest_framework/mixins.py\\\", line 19, in create\\n    self.perform_create(serializer)\\n  File \\\"/opt/ke-chain/pim3-test/_venv/lib/python3.8/site-packages/rest_framework/mixins.py\\\", line 24, in perform_create\\n    serializer.save()\\n  File \\\"/opt/ke-chain/pim3-test/_venv/lib/python3.8/site-packages/rest_framework/serializers.py\\\", line 212, in save\\n    self.instance = self.create(validated_data)\\n  File \\\"/opt/ke-chain/pim3-test/kechain2/users/api/serializers.py\\\", line 199, in create\\n    return self.Meta.model.create_action(**validated_data)\\n  File \\\"/opt/ke-chain/pim3-test/kechain2/users/models.py\\\", line 99, in create_action\\n    user.save()\\n  File \\\"/opt/ke-chain/pim3-test/_venv/lib/python3.8/site-packages/django/contrib/auth/base_user.py\\\", line 67, in save\\n    super().save(*args, **kwargs)\\n  File \\\"/opt/ke-chain/pim3-test/_venv/lib/python3.8/site-packages/django/db/models/base.py\\\", line 739, in save\\n    self.save_base(using=using, force_insert=force_insert,\\n  File \\\"/opt/ke-chain/pim3-test/_venv/lib/python3.8/site-packages/django/db/models/base.py\\\", line 776, in save_base\\n    updated = self._save_table(\\n  File \\\"/opt/ke-chain/pim3-test/_venv/lib/python3.8/site-packages/django/db/models/base.py\\\", line 881, in _save_table\\n    results = self._do_insert(cls._base_manager, using, fields, returning_fields, raw)\\n  File \\\"/opt/ke-chain/pim3-test/_venv/lib/python3.8/site-packages/django/db/models/base.py\\\", line 919, in _do_insert\\n    return manager._insert(\\n  File \\\"/opt/ke-chain/pim3-test/_venv/lib/python3.8/site-packages/django/db/models/manager.py\\\", line 85, in manager_method\\n    return getattr(self.get_queryset(), name)(*args, **kwargs)\\n  File \\\"/opt/ke-chain/pim3-test/_venv/lib/python3.8/site-packages/django/db/models/query.py\\\", line 1270, in _insert\\n    return query.get_compiler(using=using).execute_sql(returning_fields)\\n  File \\\"/opt/ke-chain/pim3-test/_venv/lib/python3.8/site-packages/django/db/models/sql/compiler.py\\\", line 1416, in execute_sql\\n    cursor.execute(sql, params)\\n  File \\\"/opt/ke-chain/pim3-test/_venv/lib/python3.8/site-packages/django/db/backends/utils.py\\\", line 98, in execute\\n    return super().execute(sql, params)\\n  File \\\"/opt/ke-chain/pim3-test/_venv/lib/python3.8/site-packages/sentry_sdk/integrations/django/__init__.py\\\", line 544, in execute\\n    return real_execute(self, sql, params)\\n  File \\\"/opt/ke-chain/pim3-test/_venv/lib/python3.8/site-packages/django/db/backends/utils.py\\\", line 66, in execute\\n    return self._execute_with_wrappers(sql, params, many=False, executor=self._execute)\\n  File \\\"/opt/ke-chain/pim3-test/_venv/lib/python3.8/site-packages/django/db/backends/utils.py\\\", line 75, in _execute_with_wrappers\\n    return executor(sql, params, many, context)\\n  File \\\"/opt/ke-chain/pim3-test/_venv/lib/python3.8/site-packages/django/db/backends/utils.py\\\", line 84, in _execute\\n    return self.cursor.execute(sql, params)\\n  File \\\"/opt/ke-chain/pim3-test/_venv/lib/python3.8/site-packages/django/db/utils.py\\\", line 90, in __exit__\\n    raise dj_exc_value.with_traceback(traceback) from exc_value\\n  File \\\"/opt/ke-chain/pim3-test/_venv/lib/python3.8/site-packages/django/db/backends/utils.py\\\", line 84, in _execute\\n    return self.cursor.execute(sql, params)\\ndjango.db.utils.IntegrityError: duplicate key value violates unique constraint \\\"users_user_username_key\\\"\\nDETAIL:  Key (username)=(__delete_me) already exists.\\n\\n\"}]}"}, "headers": {"Server": ["nginx"], "Date": ["Mon, 20 Jun 2022 12:55:39 GMT"], "Content-Type": ["application/json"], "Content-Length": ["12591"], "Connection": ["keep-alive"], "x-frame-options": ["SAMEORIGIN"], "vary": ["Accept-Language, Cookie"], "content-language": ["en"], "strict-transport-security": ["max-age=15768000; includeSubDomains"], "x-content-type-options": ["nosniff"], "x-xss-protection": ["1; mode=block"], "referrer-policy": ["same-origin"]}, "status": {"code": 500, "message": "Internal Server Error"}, "url": "<API_URL>/api/users.json"}, "recorded_at": "2022-06-20T12:55:39"}], "recorded_with": "betamax/0.8.1"}